#VRML_SIM R2025a utf8
# license: Apache License 2.0
# license url: http://www.apache.org/licenses/LICENSE-2.0
# This is a proto file for Webots for the Dofbot
# Extracted from: /Users/elit3guzhva/git_projects/dofbot/simulation/webots/dofbot.sim.urdf

PROTO Dofbot [
  field  SFVec3f     translation     0 0 0
  field  SFRotation  rotation        0 0 1 0
  field  SFString    name            "Dofbot"  # Is `Robot.name`.
  field  SFString    controller      "void"    # Is `Robot.controller`.
  field  MFString    controllerArgs  []        # Is `Robot.controllerArgs`.
  field  SFString    customData      ""        # Is `Robot.customData`.
  field  SFBool      supervisor      FALSE     # Is `Robot.supervisor`.
  field  SFBool      synchronization TRUE      # Is `Robot.synchronization`.
  field  SFBool      selfCollision   FALSE     # Is `Robot.selfCollision`.
]
{
  Robot {
    translation IS translation
    rotation IS rotation
    controller IS controller
    controllerArgs IS controllerArgs
    customData IS customData
    supervisor IS supervisor
    synchronization IS synchronization
    selfCollision IS selfCollision
    children [
      Shape {
        appearance DEF base_link_material PBRAppearance {
          baseColor 0.592157 0.666667 0.682353
          roughness 1.000000
          metalness 0
        }
        geometry DEF base_link Mesh {
          url "../../../description/meshes/base_link.STL"
        }
      }
      HingeJoint {
        jointParameters HingeJointParameters {
          axis 0.000000 0.010805 0.999942
          anchor 0.000000 0.000000 0.066050
        }
        device [
          RotationalMotor {
            name "joint1"
            maxVelocity 1.0
            minPosition -1.5708
            maxPosition 1.5708
            maxTorque 30.0
          }
          PositionSensor {
            name "joint1_sensor"
          }
        ]
        endPoint Solid {
          translation 0.000000 0.000000 0.066050
          rotation -1.000000 0.000000 0.000000 0.010805
          children [
            Shape {
              appearance DEF link1_material PBRAppearance {
                baseColor 0.000000 0.627451 0.235294
                roughness 1.000000
                metalness 0
              }
              geometry DEF link1 Mesh {
                url "../../../description/meshes/link1.STL"
              }
            }
            HingeJoint {
              jointParameters HingeJointParameters {
                axis 1.000000 0.000000 -0.000004
                anchor 0.000000 -0.000319 0.041450
              }
              device [
                RotationalMotor {
                  name "joint2"
                  maxVelocity 1.0
                  minPosition -1.5708
                  maxPosition 1.5708
                  maxTorque 30.0
                }
                PositionSensor {
                  name "joint2_sensor"
                }
              ]
              endPoint Solid {
                translation 0.000000 -0.000319 0.041450
                rotation 0.000000 1.000000 0.000000 1.570800
                children [
                  Shape {
                    appearance DEF link2_material PBRAppearance {
                      baseColor 0.592157 0.666667 0.682353
                      roughness 1.000000
                      metalness 0
                    }
                    geometry DEF link2 Mesh {
                      url "../../../description/meshes/link2.STL"
                    }
                  }
                  HingeJoint {
                    jointParameters HingeJointParameters {
                      axis 0.000000 0.000000 1.000000
                      anchor -0.082850 0.000000 0.000000
                    }
                    device [
                      RotationalMotor {
                        name "joint3"
                        maxVelocity 1.0
                        minPosition -1.5708
                        maxPosition 1.5708
                        maxTorque 30.0
                      }
                      PositionSensor {
                        name "joint3_sensor"
                      }
                    ]
                    endPoint Solid {
                      translation -0.082850 0.000000 0.000000
                      children [
                        Shape {
                          appearance DEF link3_material PBRAppearance {
                            baseColor 0.000000 0.627451 0.235294
                            roughness 1.000000
                            metalness 0
                          }
                          geometry DEF link3 Mesh {
                            url "../../../description/meshes/link3.STL"
                          }
                        }
                        HingeJoint {
                          jointParameters HingeJointParameters {
                            axis 0.000000 0.000000 1.000000
                            anchor -0.082850 0.000000 0.000000
                          }
                          device [
                            RotationalMotor {
                              name "joint4"
                              maxVelocity 1.0
                              minPosition -1.5708
                              maxPosition 1.5708
                              maxTorque 30.0
                            }
                            PositionSensor {
                              name "joint4_sensor"
                            }
                          ]
                          endPoint Solid {
                            translation -0.082850 0.000000 0.000000
                            rotation 0.000000 0.000000 1.000000 0.008308
                            children [
                              Shape {
                                appearance DEF link4_material PBRAppearance {
                                  baseColor 0.592157 0.666667 0.682353
                                  roughness 1.000000
                                  metalness 0
                                }
                                geometry DEF link4 Mesh {
                                  url "../../../description/meshes/link4.STL"
                                }
                              }
                              HingeJoint {
                                jointParameters HingeJointParameters {
                                  axis -1.000000 0.000000 0.000796
                                  anchor -0.073850 -0.001000 0.000000
                                }
                                device [
                                  RotationalMotor {
                                    name "joint5"
                                    maxVelocity 1.0
                                    minPosition -1.5708
                                    maxPosition 3.1416
                                    maxTorque 30.0
                                  }
                                  PositionSensor {
                                    name "joint5_sensor"
                                  }
                                ]
                                endPoint Solid {
                                  translation -0.073850 -0.001000 0.000000
                                  rotation 0.000000 -1.000000 0.000000 1.570000
                                  children [
                                    Shape {
                                      appearance DEF link5_material PBRAppearance {
                                        roughness 1.000000
                                        metalness 0
                                      }
                                      geometry DEF link5 Mesh {
                                        url "../../../description/meshes/link5.STL"
                                      }
                                    }
                                  ]
                                  name "link5"
                                  boundingObject USE link5
                                  physics Physics {
                                  }
                                }
                              }
                            ]
                            name "link4"
                            boundingObject USE link4
                            physics Physics {
                            }
                          }
                        }
                      ]
                      name "link3"
                      boundingObject USE link3
                      physics Physics {
                      }
                    }
                  }
                ]
                name "link2"
                boundingObject USE link2
                physics Physics {
                }
              }
            }
          ]
          name "link1"
          boundingObject USE link1
          physics Physics {
          }
        }
      }
    ]
    name IS name
    # Fixed base for manipulator stability.
  }
}
